<?xml version="1.0" ?>

<robot name="dasautonomeauto" xmlns:xacro="http://www.ros.org/wiki/xacro">
  <!-- =============== Link & Joint =============== -->
  <!-- Base Footprint -->
  <link name="base_footprint"/>
  <joint name="base_link_joint" type="fixed">
    <origin rpy="0 0 0" xyz="0 0 0"/>
    <parent link="base_footprint"/>
    <child link="base_link"/>
  </joint>


  <link name="base_link">
    <visual>
      <geometry>
        <mesh filename="file://$(find sdv_description)/meshes/DAE/base/base_link.dae" />
      </geometry>
    </visual>
    <collision>
      <geometry>
        <mesh filename="file://$(find sdv_description)/meshes/STL/base/base_link.dae" />
      </geometry>
    </collision>
    <inertial>
      <origin xyz="0 0 0"/>
      <mass value="10"/>
      <inertia ixx="0.237" ixy="0" ixz="0" iyy="0.207" iyz="-0.035" izz="0.351"/>
    </inertial>
  </link>


  <joint name="front_right_steering_joint" type="revolute">
    <!-- revolute -->
    <origin rpy="3.141592653589793 0 0" xyz="-0.35 -0.15 0"/>
    <parent link="base_link"/>
    <child link="front_right_steering_link"/>
    <limit effort="5" lower="-2.1" upper="2.1" velocity="6.28"/>
    <axis xyz="0 0 1"/>
  </joint>
  <link name="front_right_steering_link">
    <visual>
      <geometry>
        <mesh filename="file://$(find sdv_description)/meshes/DAE/suspension/front_right_sus.dae" />
      </geometry>
    </visual>
    <collision>
      <geometry>
        <mesh filename="file://$(find sdv_description)/meshes/STL/suspension/front_right_sus.stl" />
      </geometry>
    </collision>
    <inertial>
      <origin xyz="0 0 -0.02"/>
      <mass value="0.15"/>
      <inertia ixx="0.00001" ixy="0" ixz="0" iyy="0.00001" iyz="0" izz="0.000004"/>
    </inertial>
  </link>


  <joint name="front_left_steering_joint" type="revolute">
    <!-- revolute -->
    <origin rpy="3.141592653589793 0 0" xyz="-0.35 0.15 0"/>
    <parent link="base_link"/>
    <child link="front_left_steering_link"/>
    <limit effort="5" lower="-2.1" upper="2.1" velocity="6.28"/>
    <axis xyz="0 0 1"/>
  </joint>
  <link name="front_left_steering_link">
    <visual>
      <geometry>

        <mesh filename="file://$(find sdv_description)/meshes/DAE/suspension/front_left_sus.dae" />
      </geometry>
    </visual>
    <collision>
      <geometry>
        <mesh filename="file://$(find sdv_description)/meshes/STL/suspension/front_left_sus.stl" />

      </geometry>
    </collision>
    <inertial>
      <origin xyz="0 0 -0.02"/>
      <mass value="0.15"/>
      <inertia ixx="0.00001" ixy="0" ixz="0" iyy="0.00001" iyz="0" izz="0.000004"/>
    </inertial>
  </link>



  <joint name="front_right_wheel_joint" type="continuous">
    <!--continuous-->
    <origin xyz="0.083562 0.02 -0.099586"/>
    <parent link="front_right_steering_link"/>
    <child link="front_right_wheel_link"/>
    <limit effort="1.5" velocity="20"/>
    <axis xyz="0 1 0"/>
  </joint>
  <link name="front_right_wheel_link">
    <visual>
      <geometry>
        <mesh filename="file://$(find sdv_description)/meshes/DAE/front_wheel/wheel.dae" />
      </geometry>
    </visual>
    <collision>
      <geometry>
        <mesh filename="file://$(find sdv_description)/meshes/STL/front_wheel/wheel.stl" />
      </geometry>
    </collision>
    <inertial>
      <origin xyz="0 0 0"/>
      <mass value="0.137"/>
      <inertia ixx="0.00006" ixy="0" ixz="0" iyy="0.00011" iyz="0" izz="0.00006"/>
    </inertial>
  </link>




  <joint name="front_left_wheel_joint" type="continuous">
    <!--continuous-->
    <origin xyz="0.083562 -0.02 -0.099586"/>
    <parent link="front_left_steering_link"/>
    <child link="front_left_wheel_link"/>
    <limit effort="1.5" velocity="20"/>
    <axis xyz="0 -1 0"/>
  </joint>
  <link name="front_left_wheel_link">
    <visual>
      <geometry>
        <mesh filename="file://$(find sdv_description)/meshes/DAE/front_wheel/wheel.dae" />
      </geometry>
    </visual>
    <collision>
      <geometry>
        <mesh filename="file://$(find sdv_description)/meshes/STL/front_wheel/wheel.stl" />
      </geometry>
    </collision>
    <inertial>
      <origin xyz="0 0 0"/>
      <mass value="0.137"/>
      <inertia ixx="0.00006" ixy="0" ixz="0" iyy="0.00011" iyz="0" izz="0.00006"/>
    </inertial>
  </link>
  <joint name="right_wheel_joint" type="continuous">
    <origin rpy="0 0 0" xyz="0.275 -0.17 0.1"/>
    <parent link="base_link"/>
    <child link="right_wheel_link"/>
    <axis xyz="0 1 0"/>
  </joint>

  
  <link name="right_wheel_link">
    <visual>
      <geometry>

        <mesh filename="file://$(find sdv_description)/meshes/DAE/rear_wheel/wheel.dae" />

      </geometry>
    </visual>
    <collision>
      <geometry>
        <mesh filename="file://$(find sdv_description)/meshes/STL/rear_wheel/wheel.stl" />
      </geometry>
    </collision>
    <inertial>
      <origin xyz="0 0 0"/>
      <mass value="1.75"/>
      <inertia ixx="0.00458" ixy="0" ixz="0" iyy="0.00871" iyz="0" izz="0.00458"/>
    </inertial>
  </link>

  
  <joint name="left_wheel_joint" type="continuous">
    <origin rpy="0 0 3.141592653589793" xyz="0.275 0.17 0.1"/>
    <parent link="base_link"/>
    <child link="left_wheel_link"/>
    <axis xyz="0 -1 0"/>
  </joint>
  
  <link name="left_wheel_link">
    <visual>
      <geometry>
        <mesh filename="file://$(find sdv_description)/meshes/DAE/rear_wheel/wheel.dae" />
      </geometry>
    </visual>
    <collision>
      <geometry>
        <mesh filename="file://$(find sdv_description)/meshes/STL/rear_wheel/wheel.stl" />
      </geometry>
    </collision>
    <inertial>
      <origin xyz="0 0 0"/>
      <mass value="1.75"/>
      <inertia ixx="0.00458" ixy="0" ixz="0" iyy="0.00871" iyz="0" izz="0.00458"/>
    </inertial>
  </link>

  <!-- =======VELODYNE ======================= -->

  <joint name="velodyne_base_mount_joint" type="fixed">
    <origin rpy="0 3.141592653589793 0" xyz="0 0 -0.4"/>
    <parent link="base_link"/>
    <child link="velodyne_base_link"/>
  </joint>


  <link name="velodyne_base_link">
    <inertial>
      <mass value="0.83"/>
      <origin xyz="0 0 0.03585"/>
      <inertia ixx="0.000908059425" ixy="0" ixz="0" iyy="0.000908059425" iyz="0" izz="0.0011049624"/>
    </inertial>
    <visual>
      <geometry>

        <mesh filename="file://$(find velodyne_description)/meshes/VLP16_base_1.dae" />

      </geometry>
    </visual>
    <visual>
      <geometry>
        <mesh filename="file://$(find velodyne_description)/meshes/VLP16_base_2.dae" />
      </geometry>
    </visual>
    <collision>
      <origin rpy="0 0 0" xyz="0 0 0.03585"/>
      <geometry>
        <cylinder length="0.0717" radius="0.0516"/>
      </geometry>
    </collision>
  </link>




  <joint name="velodyne_base_scan_joint" type="fixed">
    <origin rpy="0 0 0" xyz="0 0 0.0377"/>
    <parent link="velodyne_base_link"/>
    <child link="velodyne"/>
  </joint>
  <link name="velodyne">
    <inertial>
      <mass value="0.01"/>
      <origin xyz="0 0 0"/>
      <inertia ixx="1e-7" ixy="0" ixz="0" iyy="1e-7" iyz="0" izz="1e-7"/>
    </inertial>
    <visual>
      <origin xyz="0 0 -0.0377"/>
      <geometry>
        <mesh filename="file://$(find velodyne_description)/meshes/VLP16_scan.dae" />
      </geometry>
    </visual>
  </link>






  <!-- =============== Transmission =============== -->
  <transmission name="right_wheel_trans">
    <type>transmission_interface/SimpleTransmission</type>
    <joint name="right_wheel_joint">
      <hardwareInterface>hardware_interface/VelocityJointInterface</hardwareInterface>
    </joint>
    <actuator name="right_wheel_motor">
      <hardwareInterface>hardware_interface/VelocityJointInterface</hardwareInterface>
      <mechanicalReduction>30</mechanicalReduction>
    </actuator>
  </transmission>
  <transmission name="left_wheel_trans">
    <type>transmission_interface/SimpleTransmission</type>
    <joint name="left_wheel_joint">
      <hardwareInterface>hardware_interface/VelocityJointInterface</hardwareInterface>
    </joint>
    <actuator name="left_wheel_motor">
      <hardwareInterface>hardware_interface/VelocityJointInterface</hardwareInterface>
      <mechanicalReduction>30</mechanicalReduction>
    </actuator>
  </transmission>
  <!-- =============== Gazebo =============== -->
  <gazebo>
    <plugin filename="libgazebo_ros_control.so" name="gazebo_ros_control"/>
  </gazebo>
  <gazebo reference="base_link">
    <selfCollide>false</selfCollide>
    <mu1 value="0.05"/>
    <mu2 value="0.05"/>
  </gazebo>
  <gazebo reference="front_right_wheel_link">
    <selfCollide>false</selfCollide>
    <mu1 value="0.8"/>
    <mu2 value="0.8"/>
    <kp value="100000.0"/>
    <kd value="10.0"/>
  </gazebo>
  <gazebo reference="front_left_wheel_link">
    <selfCollide>false</selfCollide>
    <mu1 value="0.8"/>
    <mu2 value="0.8"/>
    <kp value="100000.0"/>
    <kd value="10.0"/>
  </gazebo>
  <gazebo reference="right_wheel_link">
    <selfCollide>false</selfCollide>
    <mu1 value="0.8"/>
    <mu2 value="0.8"/>
    <kp value="100000.0"/>
    <kd value="10.0"/>
  </gazebo>
  <gazebo reference="left_wheel_link">
    <selfCollide>false</selfCollide>
    <mu1 value="0.8"/>
    <mu2 value="0.8"/>
    <kp value="100000.0"/>
    <kd value="10.0"/>
  </gazebo>
  <gazebo reference="front_right_steering_link">
    <selfCollide>false</selfCollide>
    <mu1 value="0.05"/>
    <mu2 value="0.05"/>
  </gazebo>
  <gazebo reference="front_left_steering_link">
    <selfCollide>false</selfCollide>
    <mu1 value="0.05"/>
    <mu2 value="0.05"/>
  </gazebo>


  <gazebo>

    <plugin name="gazebo_ros_ackermann_drive" filename="libgazebo_ros_ackermann_drive.so">

      <ros>
        <!-- <namespace></namespace> -->
        <remapping>cmd_vel:=cmd_vel</remapping>
        <remapping>odom:=odom</remapping>

      </ros>

      <update_rate>100.0</update_rate>

      <!-- wheels -->
      <front_left_joint>left_front_axle</front_left_joint>
      <front_right_joint>right_front_axle</front_right_joint>

      <rear_left_joint>left_rear_axle</rear_left_joint>
      <rear_right_joint>right_rear_axle</rear_right_joint>

      <left_steering_joint>left_steering_joint</left_steering_joint>
      <right_steering_joint>right_steering_joint</right_steering_joint>

      <!-- Max absolute steer angle for tyre in radians-->
      <!-- Any cmd_vel angular z greater than this would be capped -->
      <max_steer>1.01</max_steer>

      <!-- Max absolute steering angle of steering wheel -->
      <max_steering_angle>6.85</max_steering_angle>

      <!-- Max absolute linear speed in m/s -->
      <max_speed>20</max_speed>

      <!-- PID tuning -->
    <left_steering_pid_gain>1500 0 1</left_steering_pid_gain>
    <left_steering_i_range>0 0</left_steering_i_range>
    <right_steering_pid_gain>1500 0 1</right_steering_pid_gain>
    <right_steering_i_range>0 0</right_steering_i_range>
    <linear_velocity_pid_gain>1000 0 1</linear_velocity_pid_gain>
    <linear_velocity_i_range>0 0</linear_velocity_i_range>

      <!-- output -->
      <publish_odom>true</publish_odom>
      <publish_odom_tf>true</publish_odom_tf>
      <publish_wheel_tf>true</publish_wheel_tf>
      <publish_distance>false</publish_distance>

      <odometry_frame>odom</odometry_frame>
      <robot_base_frame>base_footprint</robot_base_frame>

    </plugin>

  </gazebo>

</robot>
